"""Exerc√≠cio 6: Erro ao Trabalhar com Dicion√°rios

O c√≥digo abaixo tenta acessar uma chave que n√£o existe no dicion√°rio e ainda pede uma entrada do usu√°rio.

```
dados = {
    "nome": "Isaac ",
    "idade": 25,
    "cidade": "S√£o Paulo"
}

chave = input("Digite a chave que deseja acessar: ")

print(f"O valor da chave '{chave}' √©: {dados[chave]}")
```

Tarefa:
1Ô∏è‚É£ Teste com diferentes entradas e veja quais causam erro.
2Ô∏è‚É£ Implemente `try-except` para capturar `KeyError` e mostrar uma mensagem amig√°vel.
3Ô∏è‚É£ Pesquise sobre o m√©todo `get()` e utilize-o para evitar erros ao acessar o dicion√°rio.

üí° Dica: `dados.get("endereco", "Endere√ßo n√£o encontrado")` evita o erro."""

dados = {
    "nome": "Isaac ",
    "idade": 25,
    "cidade": "S√£o Paulo"
}

chave = input("Digite a chave que deseja acessar: ")

try:
    print(f"O valor da chave '{chave}' √©: {dados[chave]}")
except KeyError:
    valor = dados.get(chave, f"Chave: '{chave}' n√£o existe. Chaves existentes {list(dados.keys())}")
    print(valor)